<?xml version='1.0'?>

<robot  name="mower">
  <link name="base_link">
    <inertial>
      <origin xyz="0.1 -.305 0" rpy="0 0 0" />
      <mass value="13.745" />
      <inertia ixx="2.956" ixy="1.956" ixz="-0.553" iyy="3.169" iyz="-0.616" izz="5.583" />
    </inertial>
    <visual>
      <origin xyz="0.005 -.305 0" rpy="0 0 0" />
      <geometry>
        <mesh filename="package://mower_description/meshes/lawn_mower.STL" />
      </geometry>
      <material name="orange"/>
    </visual>
    <collision>
      <origin xyz="0.005 -.305 0" rpy="0 0 0" />
      <geometry>
        <mesh filename="package://mower_description/meshes/lawn_mower.STL" />
      </geometry>
    </collision>
  </link>

  <link name="wheel_right">
    <inertial>
      <origin xyz="0 0 0" rpy="0 0 0" />
      <mass value="5" />
      <inertia ixx="0" ixy="0" ixz="0" iyy="0" iyz="0" izz="0" />
    </inertial>
    <visual>
      <origin xyz="-0.1095 .4 -0.1095" rpy="0 0 0" />
      <geometry>
        <mesh filename="package://mower_description/meshes/wheel.STL" />
      </geometry>
      <material name="black"/>
    </visual>
    <collision>
      <origin xyz="0 .4 0" rpy="1.5708 0 0" />
      <geometry>
        <cylinder radius="0.1" length="0.05"/>
      </geometry>
      <surface>
        <friction>
          <ode>
            <mu>1000000</mu>
            <mu2>1000000</mu2>
            <slip1>0</slip1>
            <slip2>0</slip2>
          </ode>
        </friction>
      </surface>
    </collision>
  </link>

  <link name="wheel_left">
    <inertial>
      <origin xyz="0.1095 0.075 -0.1095" rpy="0 0 0" />
      <mass value="5" />
      <inertia ixx="0" ixy="0" ixz="0" iyy="0" iyz="0" izz="0" />
    </inertial>
    <visual>
      <origin xyz="0.1095 -.4 -0.1095" rpy="0 0 3.1417" />
      <geometry>
        <mesh filename="package://mower_description/meshes/wheel.STL" />
      </geometry>
      <material name="black"/>
    </visual>
    <collision>
      <origin xyz="0 -.4 0" rpy="1.5708 0 0" />
      <geometry>
        <cylinder radius="0.1" length="0.05"/>
      </geometry>
      <surface>
        <friction>
          <ode>
            <mu>1000000</mu>
            <mu2>1000000</mu2>
            <slip1>0</slip1>
            <slip2>0</slip2>
          </ode>
        </friction>
      </surface>
    </collision>
  </link>

  <link name="caster_right">
    <inertial>
      <origin xyz="0 0 0" rpy="0 0 0" />
      <mass value="5" />
      <inertia ixx="0" ixy="0" ixz="0" iyy="0" iyz="0" izz="0" />
    </inertial>
    <collision>
      <origin xyz="0 0 0" rpy=" 0 0 0"/>
      <geometry>
        <sphere radius="0.1"/>
      </geometry>
      <surface>
        <friction>
          <ode>
            <mu>0</mu>
            <mu2>0</mu2>
            <slip1>1.0</slip1>
            <slip2>1.0</slip2>
          </ode>
        </friction>
      </surface>
    </collision>
    <visual>
      <origin xyz="0 0 0" rpy=" 0 0 0"/>
      <geometry>
        <sphere radius="0.1"/>
      </geometry>
    </visual>
  </link>

 <link name="caster_left">
    <inertial>
      <origin xyz="0 0 0" rpy="0 0 0" />
      <mass value="5" />
      <inertia ixx="0" ixy="0" ixz="0" iyy="0" iyz="0" izz="0" />
    </inertial>
    <collision>
      <origin xyz="0 0 0" rpy=" 0 0 0"/>
      <geometry>
        <sphere radius="0.1"/>
      </geometry>
      <surface>
        <friction>
          <ode>
            <mu>0</mu>
            <mu2>0</mu2>
            <slip1>1.0</slip1>
            <slip2>1.0</slip2>
          </ode>
        </friction>
      </surface>
    </collision>
    <visual>
      <origin xyz="0 0 0" rpy=" 0 0 0"/>
      <geometry>
        <sphere radius="0.1"/>
      </geometry>
    </visual>
  </link>

  <joint name="base_to_wheel_left" type="continuous">
    <origin xyz="0 0 0" rpy="0 0 0" />
    <parent link="base_link" />
    <child link="wheel_left" />
    <axis xyz="0 1 0" />
    <limit effort="10000" velocity="1000"/>
    <joint_properties damping="1.0" friction="1.0"/>
  </joint>

  <joint name="base_to_wheel_right" type="continuous">
    <origin xyz="0 0 0" rpy="0 0 0" />
    <parent link="base_link" />
    <child link="wheel_right" />
    <axis xyz="0 1 0" />
    <limit effort="10000" velocity="1000"/>
    <joint_properties damping="1.0" friction="1.0"/>
  </joint>

  <joint name="base_to_caster_left" type="continuous">
    <origin xyz="0.5 0.4 0" rpy="0 0 0" />
    <parent link="base_link" />
    <child link="caster_left" />
    <axis xyz="0 1 0" />
  </joint>

  <joint name="base_to_caster_right" type="continuous">
    <origin xyz="0.5 -0.4 0" rpy="0 0 0" />
    <parent link="base_link" />
    <child link="caster_right" />
    <axis xyz="0 1 0" />
  </joint>


  <link name="camera">
    <collision>
      <origin xyz="0 0 0" rpy="0 0 3.1417"/>
      <geometry>
        <box size="0.02 0.05 0.05"/>
      </geometry>
    </collision>

    <visual>
      <origin xyz="0 0 0" rpy="0 0 3.1417"/>
      <geometry>
        <box size="0.02 0.05 0.05"/>
      </geometry>
      <material name="black"/>
    </visual>

    <inertial>
      <mass value=".05" />
      <origin xyz="0 0 0" rpy="0 0 0"/>
      <inertia ixx="1e-6" ixy="0" ixz="0" iyy="1e-6" iyz="0" izz="1e-6" />
    </inertial>
  </link>

  <joint name="camera_joint" type="fixed">
    <origin xyz=".365 0 0.1" rpy="0 -.1 0"/>
    <parent link="base_link"/>
    <child link="camera"/>
  </joint>


  <link name="GPSantenna">
    <collision>
      <origin xyz="0 0 0" rpy="0 0 0"/>
      <geometry>
        <box size="0.02 0.02 0.01"/>
      </geometry>
    </collision>

    <visual>
      <origin xyz="0 0 0" rpy="0 0 0"/>
      <geometry>
        <box size="0.02 0.02 0.01"/>
      </geometry>
      <material name="black"/>
    </visual>

    <inertial>
      <mass value=".05" />
      <origin xyz="0 0 0" rpy="0 0 0"/>
      <inertia ixx="1e-6" ixy="0" ixz="0" iyy="1e-6" iyz="0" izz="1e-6" />
    </inertial>
  </link>

  <joint name="GPSantenna_joint" type="fixed">
    <origin xyz="0 0 0.3" rpy="0 0 0"/>
    <parent link="base_link"/>
    <child link="GPSantenna"/>
  </joint>




 <gazebo>
    <plugin name="differential_drive_controller" filename="libgazebo_ros_diff_drive.so">
      <legacyMode>false</legacyMode>
      <alwaysOn>true</alwaysOn>
      <updateRate>10</updateRate>
      <leftJoint>base_to_wheel_left</leftJoint>
      <rightJoint>base_to_wheel_right</rightJoint>
      <wheelSeparation>0.8</wheelSeparation>
      <wheelDiameter>0.2</wheelDiameter>
      <wheelTorque>10000</wheelTorque>
      <wheelAcceleration>100</wheelAcceleration>
      <publishWheelTF>true</publishWheelTF>
      <publishWheelJointState>true</publishWheelJointState>
      <commandTopic>cmd_vel</commandTopic>
      <odometryTopic>odom</odometryTopic>
      <odometryFrame>odom</odometryFrame>
      <robotBaseFrame>base_link</robotBaseFrame>
    </plugin>
  </gazebo>

  <gazebo>
   <plugin name="gazebo_ros_control" filename="libgazebo_ros_control.so">
      <robotNamespace>/mower</robotNamespace>
   </plugin>
  </gazebo>

  <gazebo reference="camera">
    <material>Gazebo/Black</material>
    <sensor type="camera" name="camera1">
      <update_rate>30.0</update_rate>
      <camera name="head">
        <horizontal_fov>1.3962634</horizontal_fov>
        <image>
          <width>800</width>
          <height>800</height>
          <format>R8G8B8</format>
        </image>
        <clip>
          <near>0.02</near>
          <far>300</far>
        </clip>
      </camera>
      <plugin name="camera_controller" filename="libgazebo_ros_camera.so">
        <alwaysOn>true</alwaysOn>
        <updateRate>0.0</updateRate>
        <cameraName>mower/camera1</cameraName>
        <imageTopicName>image_raw</imageTopicName>
        <cameraInfoTopicName>camera_info</cameraInfoTopicName>
        <frameName>camera</frameName>
        <hackBaseline>0.07</hackBaseline>
        <distortionK1>0.0</distortionK1>
        <distortionK2>0.0</distortionK2>
        <distortionK3>0.0</distortionK3>
        <distortionT1>0.0</distortionT1>
        <distortionT2>0.0</distortionT2>
      </plugin>
    </sensor>
  </gazebo>


  <gazebo>
    <plugin name="novatel_gps_sim" filename="libhector_gazebo_ros_gps.so">
      <alwaysOn>1</alwaysOn>
      <updateRate>10.0</updateRate>
      <bodyName>GPSantenna</bodyName>
      <topicName>fix</topicName>
      <velocityTopicName>fix_velocity</velocityTopicName>
      <drift>0 0 0</drift>
      <gaussianNoise>0.00 0.00 0.00</gaussianNoise>
      <velocityDrift>0 0 0</velocityDrift>
      <velocityGaussianNoise>0.00 0.00 0.00</velocityGaussianNoise>
    </plugin>
</gazebo>



  <gazebo reference="base_link">
      <material>Gazebo/Orange</material>
      <mu1 value="0" />
      <mu2 value="0" />
  </gazebo>
  <gazebo reference="wheel_left">
      <material>Gazebo/White</material>
      <mu1 value="10000.0" />
      <mu2 value="10000.0" />
  </gazebo>
  <gazebo reference="wheel_right">
      <material>Gazebo/White</material>
      <mu1 value="10000.0" />
      <mu2 value="10000.0" />
  </gazebo>
  <gazebo reference="camera">
      <material>Gazebo/Black</material>
  </gazebo>
  <gazebo reference="antenna1">
      <material>Gazebo/Black</material>
  </gazebo>
  <gazebo reference="antenna2">
      <material>Gazebo/Black</material>
  </gazebo>
  <gazebo reference="antenna3">
      <material>Gazebo/Black</material>
  </gazebo>

  <gazebo reference="base_to_wheel_left">
      <mu1 value="1000.0" />
      <mu2 value="1000.0" />
      <kp value="10000.0" />
      <kd value="0.00001" />
      <maxVel value="100.0" />
      <minDepth value="0.0001" />
  </gazebo>    
  <gazebo reference="base_to_wheel_right">
      <mu1 value="1000.0" />
      <mu2 value="1000.0" />
      <kp value="1000.0" />
      <kd value="0.00001" />
      <maxVel value="100.0" />
      <minDepth value="0.0001" />
  </gazebo>


</robot>

